Workbook
Name Email: [1]auditoria!#REF!
Name Finspec: [1]auditoria!#REF!
Name Productos: [1]auditoria!$H$6
Name Razsoc: [1]auditoria!#REF!
Name Representante: [1]auditoria!#REF!
Name responsable: [1]auditoria!$H$5
Name Ruc: [1]auditoria!#REF!
Name tabla: [2]resumen!$D$12
Name tabla: [1]auditoria!$D$8
Name Telefono: [1]auditoria!#REF!
Name Direccion: #REF!

Sheet 📋 INSTRUCTIVO
B2: 📋 INSTRUCTIVO — CÓMO USAR ESTA LISTA DE CHEQUEO BPM
B3: ¿QUÉ ES ESTA LISTA?
B4: Esta herramienta le permite evaluar el cumplimiento de las Buenas Prácticas de Manufactura (BPM) en su planta de alimentos. Cada pregunta representa un requisito sanitario. Solo debe indicar si cumple o no, y anotar hallazgos. ¡Es muy sencillo!
B6: PASOS PARA DILIGENCIAR
B7: PASO 1 | C7: Vaya a la pestaña "📝 AUDITORIA" (parte inferior de la pantalla).
B8: PASO 2 | C8: Llene los datos de cabecera: Empresa, Auditor, Fecha.
B9: PASO 3 | C9: Para CADA pregunta en la columna "Puntaje obtenido", haga clic en la celda y seleccione del menú desplegable: ✅ 2 = CUMPLE completamente ⚠️ 1 = CUMPLE PARCIALMENTE ❌ 0 = NO CUMPLE
B10: PASO 4 | C10: Si el ítem NO APLICA a su planta, escriba "NA" en la celda de puntaje.
B11: PASO 5 | C11: En la columna "Hallazgo / Seguimiento", describa brevemente qué observó, qué falta o qué acción debe tomarse.
B12: PASO 6 | C12: Los totales y porcentajes se calculan AUTOMÁTICAMENTE. Al terminar, revise la pestaña "📊 RESUMEN".
B14: TABLA DE PUNTUACIÓN — ¿QUÉ PUNTAJE ASIGNAR?
B15: 2 — CUMPLE | C15: El requisito se cumple de forma COMPLETA. Hay evidencia, registros y se aplica siempre.
B16: 1 — CUMPLE PARCIAL | C16: El requisito se cumple ALGUNAS VECES o de forma incompleta. Hay oportunidades de mejora.
B17: 0 — NO CUMPLE | C17: El requisito NO se cumple. No hay evidencia ni práctica establecida.
B18: NA — NO APLICA | C18: El requisito no es aplicable a las actividades de su planta (Ej: si no usan vapor, el ítem de vapor = NA).
B20: INTERPRETACIÓN DE RESULTADOS
B21: 91% – 100% | C21: EXCELENTE ✅ La planta tiene un sistema BPM muy bien implementado.
B22: 76% – 90% | C22: BUENO 👍 Hay buenas prácticas. Atender las brechas encontradas.
B23: 61% – 75% | C23: REGULAR ⚠️ Se requieren acciones de mejora en varios puntos críticos.
B24: ≤ 61% | C24: DEFICIENTE ❌ Alto riesgo sanitario. Se requieren acciones inmediatas.
B26: 💡 CONSEJOS ÚTILES
B27: • Registros | C27: Si el ítem menciona 'registros', verifique que existan documentos físicos o digitales que demuestren el cumplimiento.
B28: • Programas | C28: Si el ítem menciona 'programa', busque si tienen un documento escrito con responsables, frecuencias y procedimientos.
B29: • Verificación | C29: Recorra físicamente la planta mientras diligencia. No responda solo de memoria.
B30: • Hallazgos | C30: Sea específico en los hallazgos. Ejemplo: 'La puerta del almacén tiene una abertura de 3 cm, debe reducirse a ≤1 cm'.
B31: • Acción | C31: Después de la auditoría, use los hallazgos para crear un Plan de Acción con responsables y fechas.
B33: 👆 Cuando esté listo, haga clic en la pestaña 📝 AUDITORIA para comenzar.

Sheet 📝 AUDITORIA
A2: LISTA DE CHEQUEO — VERIFICACIÓN SISTEMA BPM / HACCP
A3: Empresa / Planta: | E3: ← Escriba el nombre aquí
A4: Auditor: | E4: Fecha:
A7: N° | B7: ASPECTO A EVALUAR | C7: Puntaje Máximo | D7: Puntaje Obtenido (0, 1 ó 2) | E7: % de Cumplimiento | F7: Hallazgo / Seguimiento (Describa qué observó)
A8: I | B8: PRINCIPIOS GENERALES DE HIGIENE | C8: =+C9+C43+C66+C70+C75+C78+C83+C122 -> 148 | D8: =+D9+D43+D66+D70+D75+D78+D83+D122 -> 0 | E8: =D8/C8 -> 0
A9: I.1 | B9: PROYECTO Y CONSTRUCCION DE LAS INSTALACIONES | C9: =+C10+C13 +C22+C26+C31+C36+C39 -> 52 | D9: =+D10+D13+D22+D26+D31+D36+D39 -> 0 | E9: =+D9/C9 -> 0
A10: I.1.1 | B10: Ubicación | C10: =SUM(C11:C12) -> 4 | D10: =SUM(D11:D12) -> 0 | E10: =+D10/C10 -> 0
A11: I.1.1.1 | B11: El establecimiento es exclusivo para la producción de alimentos y no tiene conexión directa con las actividades de la vivienda; además, se mantiene alejado de fuentes de contaminación directa (Ejem: zonas de basura) | C11: 2 | F11: ← Escriba aquí el hallazgo...
A12: I.1.1.2 | B12: El diseño del establecimiento permite el flujo adecuado de personal, materia prima, equipos rodantes, residuos, otros, evitando la contaminación cruzada. | C12: 2 | F12: ← Escriba aquí el hallazgo...
A13: I.1.2 | B13: Almacenes | C13: =SUM(C14:C21) -> 16 | D13: =SUM(D14:D21) -> 0 | E13: =+D13/C13 -> 0
A14: I.1.2.1 | B14: Los almacenes están cerrados y protegidos contra el ingreso de agentes contaminantes. La materia prima, insumos y producto terminado se almacenan en ambientes separados o distribuidos de modo que se evite contaminación cruzada. | C14: 2 | F14: ← Escriba aquí el hallazgo...
A15: I.1.2.2 | B15: Las paredes, pisos y techos de los almacenes son de material sanitario, superficies lisas y recubiertas con pintura lavable de colores claros; así mismo su diseño permite una fácil limpieza. La altura de los techos reduce al mínimo la condensación de agua y formación de mohos. | C15: 2 | F15: ← Escriba aquí el hallazgo...
A16: I.1.2.3 | B16: Las ventanas u otras aberturas diseñadas para tal fin, están provistas de medios que impiden el ingreso de insectos y contaminantes; así mismo, su diseño evita la acumulación de suciedad. | C16: 2 | F16: ← Escriba aquí el hallazgo...
A17: I.1.2.4 | B17: Las puertas son de superficie lisa y fáciles de limpiar. Espacio entre puerta y piso no superior a 1 cm | C17: 2 | F17: ← Escriba aquí el hallazgo...
A18: I.1.2.5 | B18: Los pisos cuentan con declive hacia canaletas o sumideros para facilitar el lavado y escurrimiento de líquidos. Existen uniones a media caña entre piso-pared y pared-techo | C18: 2 | F18: ← Escriba aquí el hallazgo...
A19: I.1.2.6 | B19: Los productos se estiban en estibas o estantería cumpliendo las distancias establecidas (60 cm pared y 15 cm piso), de modo que permite el adecuado flujo del aire y actividades de limpieza, desinfección y control de plagas. | C19: 2 | F19: ← Escriba aquí el hallazgo...
A20: I.1.2.7 | B20: Los envases, empaques, embalajes, productos químicos de limpieza y control de plagas, se almacenan en zonas exclusivas y controladas, delimitadas e identificadas, respetando la conservación requerida. | C20: 2 | F20: ← Escriba aquí el hallazgo...
A21: I.1.2.8 | B21: Se ha previsto la instalación de medios que eviten el ingreso de plagas y/o contaminantes de modo efectivo. De existir lámparas para insectos, se encuentran operativos y se ubican en lugares donde las materia primas, insumos, productos finales, etc. no están expuestos. En caso de utilizarse cortinas de aire, estas cuentan con traslape suficiente, su altura es al ras del piso y el ancho protege el umbral o abertura. | C21: 2 | F21: ← Escriba aquí el hallazgo...
A22: I.1.3 | B22: Áreas de Procesamiento | C22: =SUM(C23:C25) -> 6 | D22: =SUM(D23:D25) -> 0 | E22: =+D22/C22 -> 0
A23: I.1.3.1 | B23: Las salas de proceso se encuentran cerradas y protegidas del ingreso de posibles agentes contaminantes (Ejemplo: aberturas entre pared-techo, pared-pared, pared-puerta, etc.). | C23: 2 | F23: ← Escriba aquí el hallazgo...
A24: I.1.3.2 | B24: Las paredes, pisos y techos de las áreas de procesamiento son de material sanitario, superficies lisas y recubiertas con pintura lavable de colores claros; así mismo su diseño permite una fácil limpieza. | C24: 2 | F24: ← Escriba aquí el hallazgo...
A25: I.1.3.3 | B25: Las ventanas u otras aberturas diseñadas para tal fin, están provistas de medios que impiden el ingreso de insectos y contaminantes; así mismo, su diseño evita la acumulación de suciedad. | C25: 2 | F25: ← Escriba aquí el hallazgo...
A26: I.1.4 | B26: Equipos | C26: =SUM(C27:C30) -> 8 | D26: =SUM(D27:D30) -> 0 | E26: =+D26/C26 -> 0
A27: I.1.4.1 | B27: Los equipos, materiales y utensilios empleados en la manipulación de alimentos son de material sanitario, no son absorbentes ni corrosibles y sus superficies son lisas y están libres de orificios y grietas. | C27: 2 | F27: ← Escriba aquí el hallazgo...
A28: I.1.4.2 | B28: Todos los ambientes refrigerados o salas climatizadas están dotados de dispositivos para la medición y registro de la temperatura, están colocados en lugares visibles y se encuentran operativos. | C28: 2 | F28: ← Escriba aquí el hallazgo...
A29: I.1.4.3 | B29: Los equipos empleados en operaciones críticas se encuentran operativos y cuentan con instrumentos y/o accesorios de medición que permitan controlar de modo efectivo los parámetros de proceso (termómetros, termógrafos, manómetros, termo higrómetros, etc.). | C29: 2 | F29: ← Escriba aquí el hallazgo...
A30: I.1.4.4 | B30: Los equipos de frío (refrigeradoras, congeladoras) son de material sanitario y sus superficies son lisas y estos se encuentran operativos de modo que mantengan la cadena de frío. | C30: 2 | F30: ← Escriba aquí el hallazgo...
A31: I.1.5 | B31: Iluminación y Ventilación | C31: =SUM(C32:C35) -> 8 | D31: =SUM(D32:D35) -> 0 | E31: =+D31/C31 -> 0
A32: I.1.5.1 | B32: La iluminación es suficiente para las operaciones que se realizan. | C32: 2 | F32: ← Escriba aquí el hallazgo...
A33: I.1.5.2 | B33: Las fuentes de luz artificial ubicadas en zonas donde se manipulan y/o almacenan los alimentos están protegidas para evitar que partículas de vidrio caigan accidentalmente a los alimentos en caso de ruptura (pantallas protectoras, micas, Films, etc.). | C33: 2 | F33: ← Escriba aquí el hallazgo...
A34: I.1.5.3 | B34: Tanto el sistema de ventilación natural y/o forzada (inyectores, presión positiva, ventiladores, etc.), como el sistema de extracción (campanas extractoras, extractores, etc.), son suficientes para evitar que el calor excesivo se convierta en vapor condensado, lo que puede representar una fuente de contaminación. Por otro lado, se percibe que la corriente de aire no se desplaza del área sucia al área limpia. | C34: 2 | F34: ← Escriba aquí el hallazgo...
A35: I.1.5.4 | B35: Los equipos de ventilación o extracción están provistos de rejillas u otra protección (mallas o filtros) de material anti corrosivo fáciles de retirar y limpiar. | C35: 2 | F35: ← Escriba aquí el hallazgo...
A36: I.1.6 | B36: Gabinetes de higiene: Manos y calzado | C36: =SUM(C37:C38) -> 4 | D36: =SUM(D37:D38) -> 0 | E36: =+D36/C36 -> 0
A37: I.1.6.1 | B37: Existen instalaciones para el lavado y desinfección de manos al ingreso, dentro de las salas de procesamiento, con de accionado indirecto. Cuentan con: agua potable a flujo continuo, jabón, desinfectante y sistema de secado de manos. | C37: 2 | F37: ← Escriba aquí el hallazgo...
A38: I.1.6.2 | B38: Se cuenta si es necesario con pediluvios para lavado de botas que no contamine las salas de procesamiento. | C38: 2 | F38: ← Escriba aquí el hallazgo...
A39: I.1.7 | B39: Servicios Higiénicos y vestuarios | C39: =SUM(C40:C42) -> 6 | D39: =SUM(D40:D42) -> 0 | E39: =+D39/C39 -> 0
A40: I.1.7.1 | B40: Cuentan con un vestuario para facilitar el cambio de vestimenta separado de hombre y mujeres. Así mismo, los casilleros permiten que los objetos personales y prendas de vestir no entren en contacto con la indumentaria de proceso. | C40: 2 | F40: ← Escriba aquí el hallazgo...
A41: I.1.7.2 | B41: Los pisos, paredes y techos de los servicios higiénicos y vestuarios son de material sanitario. | C41: 2 | F41: ← Escriba aquí el hallazgo...
A42: I.1.7.3 | B42: Los servicios higiénicos cuentan con agua potable a flujo continuo, jabón, desinfectante y sistema de secado de manos. | C42: 2 | F42: ← Escriba aquí el hallazgo...
A43: I.2 | B43: INSTALACIONES: MANTENIMIENTO Y SANEAMIENTO | C43: =+C44+C49+C53+C57+C62 -> 34 | D43: =+D44+D49+D53+D57+D62 -> 0 | E43: =+D43/C43 -> 0
...

Sheet 📊 RESUMEN
A2: 📊 RESUMEN DE CUMPLIMIENTO BPM
A3: N° | B3: ASPECTO EVALUADO | C3: Puntaje Máximo | D3: Puntaje Obtenido | E3: % Cumplimiento
A4: I | B4: PRINCIPIOS GENERALES DE HIGIENE | C4: =+C5+C13+C19+C20+C21+C22+C23+C33 -> 148 | D4: =+D5+D13+D19+D20+D21+D22+D23+D33 -> 0 | E4: =+D4/C4 -> 0
A5: I.1 | B5: PROYECTO Y CONSTRUCCION DE LAS INSTALACIONES | C5: =SUM(C6:C12) -> 52 | D5: =SUM(D6:D12) -> 0 | E5: =+D5/C5 -> 0
A6: I.1.1 | B6: Ubicación | C6: =+'📝 AUDITORIA'!C10 -> 4 | D6: =+'📝 AUDITORIA'!D10 -> 0 | E6: =+D6/C6 -> 0
A7: I.1.2 | B7: Almacenes | C7: =+'📝 AUDITORIA'!C13 -> 16 | D7: =+'📝 AUDITORIA'!D13 -> 0 | E7: =+D7/C7 -> 0
A8: I.1.3 | B8: Áreas de Procesamiento | C8: ='📝 AUDITORIA'!C22 -> 6 | D8: ='📝 AUDITORIA'!D22 -> 0 | E8: =+D8/C8 -> 0
A9: I.1.4 | B9: Equipos | C9: =+'📝 AUDITORIA'!C26 -> 8 | D9: =+'📝 AUDITORIA'!D26 -> 0 | E9: =+D9/C9 -> 0
A10: I.1.5 | B10: Iluminación y Ventilación | C10: =+'📝 AUDITORIA'!C31 -> 8 | D10: =+'📝 AUDITORIA'!D31 -> 0 | E10: =+D10/C10 -> 0
A11: I.1.6 | B11: Gabinetes de higiene: Manos y calzado | C11: =+'📝 AUDITORIA'!C36 -> 4 | D11: =+'📝 AUDITORIA'!D36 -> 0 | E11: =+D11/C11 -> 0
A12: I.1.7 | B12: Servicios Higiénicos y vestuarios | C12: =+'📝 AUDITORIA'!C39 -> 6 | D12: =+'📝 AUDITORIA'!D39 -> 0 | E12: =+D12/C12 -> 0
A13: I.2 | B13: INSTALACIONES: MANTENIMIENTO Y SANEAMIENTO | C13: =SUM(C14:C18) -> 34 | D13: =SUM(D14:D18) -> 0 | E13: =+D13/C13 -> 0
A14: I.2.1 | B14: Mantenimiento y limpieza | C14: =+'📝 AUDITORIA'!C44 -> 8 | D14: =+'📝 AUDITORIA'!D44 -> 0 | E14: =+D14/C14 -> 0
A15: I.2.2 | B15: Programa de limpieza | C15: =+'📝 AUDITORIA'!C49 -> 6 | D15: =+'📝 AUDITORIA'!D49 -> 0 | E15: =+D15/C15 -> 0
A16: I.2.3 | B16: Control de agua | C16: =+'📝 AUDITORIA'!C53 -> 6 | D16: =+'📝 AUDITORIA'!D53 -> 0 | E16: =+D16/C16 -> 0
A17: I.2.4 | B17: Control de plagas | C17: =+'📝 AUDITORIA'!C57 -> 8 | D17: =+'📝 AUDITORIA'!D57 -> 0 | E17: =+D17/C17 -> 0
A18: I.2.5 | B18: Control de residuos | C18: =+'📝 AUDITORIA'!C62 -> 6 | D18: =+'📝 AUDITORIA'!D62 -> 0 | E18: =+D18/C18 -> 0
A19: I.3 | B19: MANTENIMIENTO DE EQUIPOS Y CALIBRACIÓN DE INSTRUMENTOS (ETAPAS CRÍTICAS) | C19: =+'📝 AUDITORIA'!C66 -> 6 | D19: =+'📝 AUDITORIA'!D66 -> 0 | E19: =+D19/C19 -> 0
A20: I.4 | B20: PERSONAL | C20: =+'📝 AUDITORIA'!C70 -> 8 | D20: =+'📝 AUDITORIA'!D70 -> 0 | E20: =+D20/C20 -> 0
A21: I.5 | B21: TRANSPORTE | C21: =+'📝 AUDITORIA'!C75 -> 4 | D21: =+'📝 AUDITORIA'!D75 -> 0 | E21: =+D21/C21 -> 0
A22: I.6 | B22: CAPACITACION | C22: =+'📝 AUDITORIA'!C78 -> 8 | D22: =+'📝 AUDITORIA'!D78 -> 0 | E22: =+D22/C22 -> 0
A23: I.7 | B23: CONTROL DE OPERACIONES | C23: =SUM(C24:C31) -> 36 | D23: =SUM(D24:D31) -> 0 | E23: =+D23/C23 -> 0
A24: I.7.1 | B24: Selección y control de proveedores | C24: =+'📝 AUDITORIA'!C84 -> 4 | D24: =+'📝 AUDITORIA'!D84 -> 0 | E24: =+D24/C24 -> 0
A25: I.7.2 | B25: Control de materias primas, insumos y envases | C25: =+'📝 AUDITORIA'!C87 -> 4 | D25: =+'📝 AUDITORIA'!D87 -> 0 | E25: =+D25/C25 -> 0
A26: I.7.3 | B26: Control de almacenamiento (materias / primas / insumos producto terminado) | C26: =+'📝 AUDITORIA'!C90 -> 6 | D26: =+'📝 AUDITORIA'!D90 -> 0 | E26: =+D26/C26 -> 0
A27: I.7.4 | B27: Control de procesamiento | C27: =+'📝 AUDITORIA'!C94 -> 8 | D27: =+'📝 AUDITORIA'!D94 -> 0 | E27: =+D27/C27 -> 0
A28: I.7.5 | B28: Control de Producto terminado | C28: =+'📝 AUDITORIA'!C99 -> 8 | D28: =+'📝 AUDITORIA'!D99 -> 0 | E28: =+D28/C28 -> 0
A29: I.7.6 | B29: Trazabilidad | C29: =+'📝 AUDITORIA'!C104 -> 2 | D29: =+'📝 AUDITORIA'!D104 | E29: =+D29/C29 -> 0
A30: I.7.7 | B30: Queja de cliente | C30: =+'📝 AUDITORIA'!C106 -> 2 | D30: =+'📝 AUDITORIA'!D106 | E30: =+D30/C30 -> 0
A31: I.7.8 | B31: Recolecta de productos. | C31: =+'📝 AUDITORIA'!C108 -> 2 | D31: =+'📝 AUDITORIA'!D108 | E31: =+D31/C31 -> 0
A32: II | B32: SISTEMA HACCP | C32: =+'📝 AUDITORIA'!C111 | D32: =+'📝 AUDITORIA'!D111 | E32: =IFERROR(+D32/C32,0) -> 0
B33: CONDUCTA EMPRESARAIAL RESPONSABLE (RBC) | C33: =+'📝 AUDITORIA'!C122 | D33: =+'📝 AUDITORIA'!D122 | E33: =IFERROR(+D33/C33,0) -> 0
C34: =+C4 -> 148 | D34: =+'📝 AUDITORIA'!D128 -> 0 | E34: =+D34/C34 -> 0
B35: PUNTAJE TOTAL | C35: =+C4+C32 -> 148 | E35: =+D35/C35 -> 0
A37: INTERPRETACIÓN DE RESULTADOS
A38: 91% – 100% | B38: EXCELENTE ✅ — BPM muy bien implementado
A39: 76% – 90% | B39: BUENO 👍 — Atender las brechas encontradas
A40: 61% – 75% | B40: REGULAR ⚠️ — Acciones de mejora requeridas en varios puntos
A41: ≤ 61% | B41: DEFICIENTE ❌ — Alto riesgo sanitario. Acciones inmediatas
